<?xml version="1.0"?>
<!-- created with Phobos 0.7 -->
  <robot name="Dagu5">

    <link name="link_Body">
      <inertial>
        <origin xyz="0 0 0" rpy="0 0 0"/>
        <mass value="500.0"/>
        <inertia ixx="320.401184" ixy="1.258749" ixz="6.643906" iyy="233.601669" iyz="0.888276" izz="275.717407"/>
      </inertial>
      <visual name="Body.001">
        <origin xyz="0 0 0" rpy="0 0 0"/>
        <geometry>
          <mesh filename="meshes/Cube.001.obj" scale="2.059298 1.0 0.507399"/>
        </geometry>
      </visual>
      <collision name="Body">
        <origin xyz="0 0 -0.079788" rpy="0 0 0"/>
        <geometry>
          <box size="3.604596 2.184321 0.871725"/>
        </geometry>
      </collision>
    </link>

    <link name="link_Cube">
      <collision name="Cube">
        <origin xyz="0 0 0" rpy="0 0 0"/>
        <geometry>
          <box size="5.026439 0.104412 0.760734"/>
        </geometry>
      </collision>
    </link>

    <link name="link_Cube.001">
      <collision name="Cube.001">
        <origin xyz="0 0 0" rpy="0 0 0"/>
        <geometry>
          <box size="5.026439 0.104412 0.760734"/>
        </geometry>
      </collision>
    </link>

    <link name="link_bl_Leg">
      <inertial>
        <origin xyz="0 0 0" rpy="0 0 0"/>
        <mass value="20.0"/>
        <inertia ixx="12.399544" ixy="-0.039453" ixz="2.498817" iyy="30.488501" iyz="-0.069001" izz="29.675409"/>
      </inertial>
      <visual name="bl_Leg.001">
        <origin xyz="0 0 0" rpy="-3.141593 0 0"/>
        <geometry>
          <mesh filename="meshes/Cube.003.obj" scale="0.68 0.126 0.353675"/>
        </geometry>
      </visual>
      <collision name="bl_Leg">
        <origin xyz="0.518794 0.013662 -0.004787" rpy="0 0 0"/>
        <geometry>
          <box size="1.837332 0.298121 0.712926"/>
        </geometry>
      </collision>
    </link>

    <link name="link_bl_Wheel">
      <inertial>
        <origin xyz="0 0 0" rpy="0 0 0"/>
        <mass value="10.0"/>
        <inertia ixx="0.250197" ixy="0" ixz="0" iyy="0.414742" iyz="-1e-06" izz="0.250197"/>
      </inertial>
      <visual name="bl_Wheel">
        <origin xyz="0 -3e-06 0" rpy="0 0 0"/>
        <geometry>
          <mesh filename="meshes/mesh20.002.obj" scale="1.8 1.8 1.8"/>
        </geometry>
      </visual>
      <collision name="Cylinder.004">
        <origin xyz="-0.005038 -0.117663 0.010326" rpy="-1.570796 0 0"/>
        <geometry>
          <cylinder radius="0.52686" length="0.166"/>
        </geometry>
      </collision>
      <collision name="Cylinder.005">
        <origin xyz="-0.005038 0.169537 0.010326" rpy="-1.570796 0 0"/>
        <geometry>
          <cylinder radius="0.52686" length="0.200036"/>
        </geometry>
      </collision>
    </link>

    <link name="link_br_Leg">
      <inertial>
        <origin xyz="0 0 0" rpy="0 0 0"/>
        <mass value="20.0"/>
        <inertia ixx="12.399544" ixy="-0.039451" ixz="2.498817" iyy="30.488501" iyz="-0.068998" izz="29.675409"/>
      </inertial>
      <visual name="br_Leg.001">
        <origin xyz="0 0 0" rpy="0 0 0"/>
        <geometry>
          <mesh filename="meshes/Cube.006.obj" scale="0.68 0.126 0.353675"/>
        </geometry>
      </visual>
      <collision name="br_Leg">
        <origin xyz="0.511115 0.014924 -0.004787" rpy="0 0 0"/>
        <geometry>
          <box size="1.837332 0.297859 0.712926"/>
        </geometry>
      </collision>
    </link>

    <link name="link_br_Wheel">
      <inertial>
        <origin xyz="0 0 0" rpy="0 0 0"/>
        <mass value="10.0"/>
        <inertia ixx="0.250197" ixy="0" ixz="0" iyy="0.414742" iyz="-2e-06" izz="0.250197"/>
      </inertial>
      <visual name="br_Wheel">
        <origin xyz="0 0 0" rpy="0 0 0"/>
        <geometry>
          <mesh filename="meshes/mesh20.003.obj" scale="1.8 1.8 1.8"/>
        </geometry>
      </visual>
      <collision name="Cylinder.006">
        <origin xyz="2e-06 0.17058 0.010326" rpy="-1.570796 0 0"/>
        <geometry>
          <cylinder radius="0.52686" length="0.200036"/>
        </geometry>
      </collision>
      <collision name="Cylinder.007">
        <origin xyz="2e-06 -0.12091 0.010326" rpy="-1.570796 0 0"/>
        <geometry>
          <cylinder radius="0.52686" length="0.177113"/>
        </geometry>
      </collision>
    </link>

    <link name="link_fl_Leg">
      <inertial>
        <origin xyz="0 0 0" rpy="0 0 0"/>
        <mass value="20.0"/>
        <inertia ixx="12.399542" ixy="-0.039453" ixz="2.498814" iyy="30.488501" iyz="-0.069" izz="29.675406"/>
      </inertial>
      <visual name="fl_Leg">
        <origin xyz="0 0 0" rpy="-3.141593 0 0"/>
        <geometry>
          <mesh filename="meshes/Cube.002.obj" scale="0.680185 0.126111 0.353675"/>
        </geometry>
      </visual>
      <collision name="fl_Leg.001">
        <origin xyz="0.528119 -0.014687 -0.004787" rpy="0 0 0"/>
        <geometry>
          <box size="1.837832 0.298121 0.712926"/>
        </geometry>
      </collision>
    </link>

    <link name="link_fl_Wheel">
      <inertial>
        <origin xyz="0 0 0" rpy="0 0 0"/>
        <mass value="10.0"/>
        <inertia ixx="0.250197" ixy="0" ixz="0" iyy="0.414742" iyz="-2e-06" izz="0.250197"/>
      </inertial>
      <visual name="fl_Wheel">
        <origin xyz="0 0 0" rpy="0 0 0"/>
        <geometry>
          <mesh filename="meshes/mesh20.obj" scale="1.8 1.8 1.8"/>
        </geometry>
      </visual>
      <collision name="Cylinder">
        <origin xyz="-0.004516 0.169534 0.010326" rpy="-1.570796 0 0"/>
        <geometry>
          <cylinder radius="0.52686" length="0.200036"/>
        </geometry>
      </collision>
      <collision name="Cylinder.001">
        <origin xyz="-0.004516 -0.117659 0.010326" rpy="-1.570796 0 0"/>
        <geometry>
          <cylinder radius="0.52686" length="0.166103"/>
        </geometry>
      </collision>
    </link>

    <link name="link_fr_Leg">
      <inertial>
        <origin xyz="0 0 0" rpy="0 0 0"/>
        <mass value="20.0"/>
        <inertia ixx="12.399542" ixy="-0.039456" ixz="2.498814" iyy="30.488501" iyz="-0.068999" izz="29.675406"/>
      </inertial>
      <visual name="fr_Leg">
        <origin xyz="0 0 0" rpy="0 0 0"/>
        <geometry>
          <mesh filename="meshes/Cube.005.obj" scale="0.680185 0.126 0.353675"/>
        </geometry>
      </visual>
      <collision name="fr_Leg.001">
        <origin xyz="0.523355 0.017102 -0.004787" rpy="0 0 0"/>
        <geometry>
          <box size="1.837831 0.297859 0.712926"/>
        </geometry>
      </collision>
    </link>

    <link name="link_fr_Wheel">
      <inertial>
        <origin xyz="0 0 0" rpy="0 0 0"/>
        <mass value="10.0"/>
        <inertia ixx="0.250197" ixy="0" ixz="0" iyy="0.414742" iyz="-2e-06" izz="0.250197"/>
      </inertial>
      <visual name="fr_Wheel">
        <origin xyz="0 0 0" rpy="0 0 0"/>
        <geometry>
          <mesh filename="meshes/mesh20.001.obj" scale="1.8 1.8 1.8"/>
        </geometry>
      </visual>
      <collision name="Cylinder.002">
        <origin xyz="-0.004516 -0.120907 0.010326" rpy="-1.570796 0 0"/>
        <geometry>
          <cylinder radius="0.52686" length="0.177113"/>
        </geometry>
      </collision>
      <collision name="Cylinder.003">
        <origin xyz="-0.004516 0.170581 0.010326" rpy="-1.570796 0 0"/>
        <geometry>
          <cylinder radius="0.52686" length="0.200036"/>
        </geometry>
      </collision>
    </link>

    <joint name="link_Cube" type="fixed">
      <origin xyz="0.015789 1.920648 -0.852022" rpy="-3.141593 0 0"/>
      <parent link="link_Body"/>
      <child link="link_Cube"/>
    </joint>

    <joint name="link_Cube.001" type="fixed">
      <origin xyz="0.015789 -2.0 -0.852022" rpy="-3.141593 0 0"/>
      <parent link="link_Body"/>
      <child link="link_Cube.001"/>
    </joint>

    <joint name="link_bl_Leg" type="fixed">
      <origin xyz="-1.2458 1.218903 -0.142793" rpy="0 2.268928 0"/>
      <parent link="link_Body"/>
      <child link="link_bl_Leg"/>
    </joint>

    <joint name="link_bl_Wheel" type="revolute">
      <origin xyz="1.101439 0.415044 0.029943" rpy="0 -0.349066 -3.141593"/>
      <parent link="link_bl_Leg"/>
      <child link="link_bl_Wheel"/>
      <limit effort="0" velocity="0"/>
    </joint>

    <joint name="link_br_Leg" type="fixed">
      <origin xyz="-1.2458 -1.2189 -0.142793" rpy="0 2.268928 0"/>
      <parent link="link_Body"/>
      <child link="link_br_Leg"/>
    </joint>

    <joint name="link_br_Wheel" type="revolute">
      <origin xyz="1.101439 -0.41505 0.029943" rpy="0 -0.349066 -3.141593"/>
      <parent link="link_br_Leg"/>
      <child link="link_br_Wheel"/>
      <limit effort="0" velocity="0"/>
    </joint>

    <joint name="link_fl_Leg" type="fixed">
      <origin xyz="1.245803 1.218903 -0.142793" rpy="0 0.872665 0"/>
      <parent link="link_Body"/>
      <child link="link_fl_Leg"/>
    </joint>

    <joint name="link_fl_Wheel" type="revolute">
      <origin xyz="1.126317 0.415044 -0.020888" rpy="3.141593 -0.349066 0"/>
      <parent link="link_fl_Leg"/>
      <child link="link_fl_Wheel"/>
      <limit effort="0" velocity="1.0"/>
    </joint>

    <joint name="link_fr_Leg" type="fixed">
      <origin xyz="1.245803 -1.2189 -0.142793" rpy="0 0.872665 0"/>
      <parent link="link_Body"/>
      <child link="link_fr_Leg"/>
    </joint>

    <joint name="link_fr_Wheel" type="revolute">
      <origin xyz="1.126317 -0.41505 -0.020888" rpy="3.141593 -0.349066 0"/>
      <parent link="link_fr_Leg"/>
      <child link="link_fr_Wheel"/>
      <limit effort="0" velocity="1.0"/>
    </joint>

  </robot>
